Workbook

Sheet Start
B2: Monthly · Weekly · Daily Planner
B3: Original planner built from the blueprint in BLUEPRINT.md. Reuse it every month.
B5: 1 Keep one clean master copy. Each month: File > Make a copy, then work in the copy. Typed events are not tied to dates.
B6: 2 Open Settings. Pick the month, year, week start, schedule start time and slot length. All dates and times update by themselves.
B7: 3 Fill the lists. Priorities (7), categories (12), habits (21) and the five numeric trackers. They appear in every dropdown on every week.
B8: 4 Plan the month. On Month: goals, monthly to-do, important dates; type events in the cells under each date.
B9: 5 Plan each week (W1 to W6). Weekly priorities, daily schedule, daily to-do, gratitude, notes. Tick a task and its text is struck through and the bar moves.
B10: 6 Track. Tick habits and enter numbers on the far right of each week tab.
B12: Good to know
B13: • Grey cells are formulas – don't type over them. White cells are yours. You may merge cells in white areas.
B14: • Days from the neighbouring month appear dimmed in a week tab. Track such a day in only one month's copy.
B15: • Weeks the month doesn't need show a red note and turn grey.
... B17: • Changing the month AFTER you typed events leaves your text on the old cells – make a new copy instead.

Sheet Settings
B1: Settings
B2: Planner setup (white cells are yours; grey cells are automatic)
B3: Month | C3: October | D3: pick from the list
B4: Year | C4: 2026 | D4: 1901 to 2100
B5: Week starts on | C5: Monday
B6: Schedule start time | C6: 0.25 | D6: type a time, e.g. 6:00 AM
B7: Schedule slot (minutes) | C7: 30
B8: Progress bar colour (hex) | C8: #3BA776 | D8: bars use this colour in Google Sheets (run the setup script)
B9: Progress track colour (hex) | C9: #E3E9EC
B11: Priorities (7 slots – colours belong to the slot)
B12: Urgent
B13: High
B14: Normal
B15: Low
B16: Waiting
B17: Someday
B18: Delegated
B21: Categories (12 slots – fill top-down, no gaps)
B22: Work
B23: Home
B24: Health
... B41: Sleep on time
B60: Label | C60: Unit | D60: Min | E60: Max / target
B61: Water | C61: glasses | D61: 0 | E61: 8
B62: Mood | C62: 1-5 | D62: 1 | E62: 5
B63: Sleep | C63: hours | D63: 0 | E63: 9
B64: Pages read | C64: pages | D64: 0 | E64: 50
B65: Exercise | C65: minutes | D65: 0 | E65: 60
B67: Weekday translations (leave blank to use English)
B68: English (fixed) | C68: Your word
B69: Sunday
B70: Monday
B71: Tuesday
B72: Wednesday
B73: Thursday
B74: Friday
B75: Saturday
B77: Month translations (display only; leave blank for English)
B78: English (fixed) | C78: Your word
B79: January
...

Sheet Month
B2: =Calc!M3 | F2: Type events directly in the cells under each date. Merge, colour or add emoji as you like.
B3: =IF(Settings!$C$94="",Settings!$B$94,Settings!$C$94)
B4: FALSE | F4: =Calc!D1 | G4: =Calc!E1 | H4: =Calc!F1 | I4: =Calc!G1 | J4: =Calc!H1 | K4: =Calc!I1 | L4: =Calc!J1
B5: FALSE | E5: =HYPERLINK("#'W1'!A1","Week 1 ▶") | F5: =IF(MONTH(Calc!D3)=Calc!$B$1,Calc!D3,"") | G5: =IF(MONTH(Calc!E3)=Calc!$B$1,Calc!E3,"") | H5: =IF(MONTH(Calc!F3)=Calc!$B$1,Calc!F3,"") | I5: =IF(MONTH(Calc!G3)=Calc!$B$1,Calc!G3,"") | J5: =IF(MONTH(Calc!H3)=Calc!$B$1,Calc!H3,"") | K5: =IF(MONTH(Calc!I3)=Calc!$B$1,Calc!I3,"") | L5: =IF(MONTH(Calc!J3)=Calc!$B$1,Calc!J3,"") | N5: =INDEX(Calc!$E$10:$E$15,1)
B6: FALSE
B7: FALSE
B8: FALSE
E9: =HYPERLINK("#'W2'!A1","Week 2 ▶") | F9: =IF(MONTH(Calc!D4)=Calc!$B$1,Calc!D4,"") | G9: =IF(MONTH(Calc!E4)=Calc!$B$1,Calc!E4,"") | H9: =IF(MONTH(Calc!F4)=Calc!$B$1,Calc!F4,"") | I9: =IF(MONTH(Calc!G4)=Calc!$B$1,Calc!G4,"") | J9: =IF(MONTH(Calc!H4)=Calc!$B$1,Calc!H4,"") | K9: =IF(MONTH(Calc!I4)=Calc!$B$1,Calc!I4,"") | L9: =IF(MONTH(Calc!J4)=Calc!$B$1,Calc!J4,"") | N9: =INDEX(Calc!$E$10:$E$15,2)
B10: =IF(Settings!$C$95="",Settings!$B$95,Settings!$C$95) | D10: =IFERROR(SUMPRODUCT((D11:D25<>"")*(B11:B25=TRUE))/SUMPRODUCT((D11:D25<>"")*1),0)
B11: FALSE
B12: FALSE
B13: FALSE | E13: =HYPERLINK("#'W3'!A1","Week 3 ▶") | F13: =IF(MONTH(Calc!D5)=Calc!$B$1,Calc!D5,"") | G13: =IF(MONTH(Calc!E5)=Calc!$B$1,Calc!E5,"") | H13: =IF(MONTH(Calc!F5)=Calc!$B$1,Calc!F5,"") | I13: =IF(MONTH(Calc!G5)=Calc!$B$1,Calc!G5,"") | J13: =IF(MONTH(Calc!H5)=Calc!$B$1,Calc!H5,"") | K13: =IF(MONTH(Calc!I5)=Calc!$B$1,Calc!I5,"") | L13: =IF(MONTH(Calc!J5)=Calc!$B$1,Calc!J5,"") | N13: =INDEX(Calc!$E$10:$E$15,3)
B14: FALSE
B15: FALSE
B16: FALSE
B17: FALSE | E17: =HYPERLINK("#'W4'!A1","Week 4 ▶") | F17: =IF(MONTH(Calc!D6)=Calc!$B$1,Calc!D6,"") | G17: =IF(MONTH(Calc!E6)=Calc!$B$1,Calc!E6,"") | H17: =IF(MONTH(Calc!F6)=Calc!$B$1,Calc!F6,"") | I17: =IF(MONTH(Calc!G6)=Calc!$B$1,Calc!G6,"") | J17: =IF(MONTH(Calc!H6)=Calc!$B$1,Calc!H6,"") | K17: =IF(MONTH(Calc!I6)=Calc!$B$1,Calc!I6,"") | L17: =IF(MONTH(Calc!J6)=Calc!$B$1,Calc!J6,"") | N17: =INDEX(Calc!$E$10:$E$15,4)
B18: FALSE
B19: FALSE
B20: FALSE
B21: FALSE | E21: =HYPERLINK("#'W5'!A1","Week 5 ▶") | F21: =IF(MONTH(Calc!D7)=Calc!$B$1,Calc!D7,"") | G21: =IF(MONTH(Calc!E7)=Calc!$B$1,Calc!E7,"") | H21: =IF(MONTH(Calc!F7)=Calc!$B$1,Calc!F7,"") | I21: =IF(MONTH(Calc!G7)=Calc!$B$1,Calc!G7,"") | J21: =IF(MONTH(Calc!H7)=Calc!$B$1,Calc!H7,"") | K21: =IF(MONTH(Calc!I7)=Calc!$B$1,Calc!I7,"") | L21: =IF(MONTH(Calc!J7)=Calc!$B$1,Calc!J7,"") | N21: =INDEX(Calc!$E$10:$E$15,5)
B22: FALSE
B23: FALSE
B24: FALSE
B25: FALSE | E25: =HYPERLINK("#'W6'!A1","Week 6 ▶") | F25: =IF(MONTH(Calc!D8)=Calc!$B$1,Calc!D8,"") | G25: =IF(MONTH(Calc!E8)=Calc!$B$1,Calc!E8,"") | H25: =IF(MONTH(Calc!F8)=Calc!$B$1,Calc!F8,"") | I25: =IF(MONTH(Calc!G8)=Calc!$B$1,Calc!G8,"") | J25: =IF(MONTH(Calc!H8)=Calc!$B$1,Calc!H8,"") | K25: =IF(MONTH(Calc!I8)=Calc!$B$1,Calc!I8,"") | L25: =IF(MONTH(Calc!J8)=Calc!$B$1,Calc!J8,"") | N25: =INDEX(Calc!$E$10:$E$15,6)
B27: =IF(Settings!$C$96="",Settings!$B$96,Settings!$C$96)
B34: =IF(Settings!$C$97="",Settings!$B$97,Settings!$C$97)

Sheet W1
B1: =Calc!M3&" · "&INDEX(Calc!$F$10:$F$15,$B$2) | H1: =Calc!$B$1
B2: 1 | D2: =HYPERLINK("#'Month'!A1","◀ Month") | H2: =HYPERLINK("#'W2'!A1","Next ›")
B3: =IF(INDEX(Calc!$E$10:$E$15,$B$2),"","This week is not used in "&Calc!$M$2&".")
BA4: =IF(Settings!$C$100="",Settings!$B$100,Settings!$C$100)
B5: =LEFT(Calc!D1,2) | C5: =LEFT(Calc!E1,2) | D5: =LEFT(Calc!F1,2) | E5: =LEFT(Calc!G1,2) | F5: =LEFT(Calc!H1,2) | G5: =LEFT(Calc!I1,2) | H5: =LEFT(Calc!J1,2) | J5: =IF(INDEX(Settings!$C$69:$C$75,WEEKDAY($N$5,1))="",INDEX(Settings!$B$69:$B$75,WEEKDAY($N$5,1)),INDEX(Settings!$C$69:$C$75,WEEKDAY($N$5,1))) | N5: =INDEX(Calc!$D$3:$J$8,$B$2,1) | P5: =IF(INDEX(Settings!$C$69:$C$75,WEEKDAY($T$5,1))="",INDEX(Settings!$B$69:$B$75,WEEKDAY($T$5,1)),INDEX(Settings!$C$69:$C$75,WEEKDAY($T$5,1))) | T5: =INDEX(Calc!$D$3:$J$8,$B$2,2) | V5: =IF(INDEX(Settings!$C$69:$C$75,WEEKDAY($Z$5,1))="",INDEX(Settings!$B$69:$B$75,WEEKDAY($Z$5,1)),INDEX(Settings!$C$69:$C$75,WEEKDAY($Z$5,1))) | Z5: =INDEX(Calc!$D$3:$J$8,$B$2,3) | AB5: =IF(INDEX(Settings!$C$69:$C$75,WEEKDAY($AF$5,1))="",INDEX(Settings!$B$69:$B$75,WEEKDAY($AF$5,1)),INDEX(Settings!$C$69:$C$75,WEEKDAY($AF$5,1))) | AF5: =INDEX(Calc!$D$3:$J$8,$B$2,4) | AH5: =IF(INDEX(Settings!$C$69:$C$75,WEEKDAY($AL$5,1))="",INDEX(Settings!$B$69:$B$75,WEEKDAY($AL$5,1)),INDEX(Settings!$C$69:$C$75,WEEKDAY($AL$5,1))) | AL5: =INDEX(Calc!$D$3:$J$8,$B$2,5) | AN5: =IF(INDEX(Settings!$C$69:$C$75,WEEKDAY($AR$5,1))="",INDEX(Settings!$B$69:$B$75,WEEKDAY($AR$5,1)),INDEX(Settings!$C$69:$C$75,WEEKDAY($AR$5,1))) | AR5: =INDEX(Calc!$D$3:$J$8,$B$2,6) | AT5: =IF(INDEX(Settings!$C$69:$C$75,WEEKDAY($AX$5,1))="",INDEX(Settings!$B$69:$B$75,WEEKDAY($AX$5,1)),INDEX(Settings!$C$69:$C$75,WEEKDAY($AX$5,1))) | AX5: =INDEX(Calc!$D$3:$J$8,$B$2,7) | BB5: =LEFT(IF(INDEX(Settings!$C$69:$C$75,WEEKDAY(INDEX(Calc!$D$3:$J$8,$B$2,1),1))="",INDEX(Settings!$B$69:$B$75,WEEKDAY(INDEX(Calc!$D$3:$J$8,$B$2,1),1)),INDEX(Settings!$C$69:$C$75,WEEKDAY(INDEX(Calc!$D$3:$J$8,$B$2,1),1))),3) | BC5: =LEFT(IF(INDEX(Settings!$C$69:$C$75,WEEKDAY(INDEX(Calc!$D$3:$J$8,$B$2,2),1))="",INDEX(Settings!$B$69:$B$75,WEEKDAY(INDEX(Calc!$D$3:$J$8,$B$2,2),1)),INDEX(Settings!$C$69:$C$75,WEEKDAY(INDEX(Calc!$D$3:$J$8,$B$2,2),1))),3) | BD5: =LEFT(IF(INDEX(Settings!$C$69:$C$75,WEEKDAY(INDEX(Calc!$D$3:$J$8,$B$2,3),1))="",INDEX(Settings!$B$69:$B$75,WEEKDAY(INDEX(Calc!$D$3:$J$8,$B$2,3),1)),INDEX(Settings!$C$69:$C$75,WEEKDAY(INDEX(Calc!$D$3:$J$8,$B$2,3),1))),3) | BE5: =LEFT(IF(INDEX(Settings!$C$69:$C$75,WEEKDAY(INDEX(Calc!$D$3:$J$8,$B$2,4),1))="",INDEX(Settings!$B$69:$B$75,WEEKDAY(INDEX(Calc!$D$3:$J$8,$B$2,4),1)),INDEX(Settings!$C$69:$C$75,WEEKDAY(INDEX(Calc!$D$3:$J$8,$B$2,4),1))),3) | BF5: =LEFT(IF(INDEX(Settings!$C$69:$C$75,WEEKDAY(INDEX(Calc!$D$3:$J$8,$B$2,5),1))="",INDEX(Settings!$B$69:$B$75,WEEKDAY(INDEX(Calc!$D$3:$J$8,$B$2,5),1)),INDEX(Settings!$C$69:$C$75,WEEKDAY(INDEX(Calc!$D$3:$J$8,$B$2,5),1))),3) | BG5: =LEFT(IF(INDEX(Settings!$C$69:$C$75,WEEKDAY(INDEX(Calc!$D$3:$J$8,$B$2,6),1))="",INDEX(Settings!$B$69:$B$75,WEEKDAY(INDEX(Calc!$D$3:$J$8,$B$2,6),1)),INDEX(Settings!$C$69:$C$75,WEEKDAY(INDEX(Calc!$D$3:$J$8,$B$2,6),1))),3) | BH5: =LEFT(IF(INDEX(Settings!$C$69:$C$75,WEEKDAY(INDEX(Calc!$D$3:$J$8,$B$2,7),1))="",INDEX(Settings!$B$69:$B$75,WEEKDAY(INDEX(Calc!$D$3:$J$8,$B$2,7),1)),INDEX(Settings!$C$69:$C$75,WEEKDAY(INDEX(Calc!$D$3:$J$8,$B$2,7),1))),3) | BI5: % | BJ5: Progress
B6: =Calc!D3 | C6: =Calc!E3 | D6: =Calc!F3 | E6: =Calc!G3 | F6: =Calc!H3 | G6: =Calc!I3 | H6: =Calc!J3 | J6: =IFERROR(SUMPRODUCT((M47:M56<>"")*(J47:J56=TRUE))/SUMPRODUCT((M47:M56<>"")*1),0) | K6: =IF(J6="","",REPT("█",ROUND(J6*14,0))&REPT("░",14-ROUND(J6*14,0))) | P6: =IFERROR(SUMPRODUCT((S47:S56<>"")*(P47:P56=TRUE))/SUMPRODUCT((S47:S56<>"")*1),0) | Q6: =IF(P6="","",REPT("█",ROUND(P6*14,0))&REPT("░",14-ROUND(P6*14,0))) | V6: =IFERROR(SUMPRODUCT((Y47:Y56<>"")*(V47:V56=TRUE))/SUMPRODUCT((Y47:Y56<>"")*1),0) | W6: =IF(V6="","",REPT("█",ROUND(V6*14,0))&REPT("░",14-ROUND(V6*14,0))) | AB6: =IFERROR(SUMPRODUCT((AE47:AE56<>"")*(AB47:AB56=TRUE))/SUMPRODUCT((AE47:AE56<>"")*1),0) | AC6: =IF(AB6="","",REPT("█",ROUND(AB6*14,0))&REPT("░",14-ROUND(AB6*14,0))) | AH6: =IFERROR(SUMPRODUCT((AK47:AK56<>"")*(AH47:AH56=TRUE))/SUMPRODUCT((AK47:AK56<>"")*1),0) | AI6: =IF(AH6="","",REPT("█",ROUND(AH6*14,0))&REPT("░",14-ROUND(AH6*14,0))) | AN6: =IFERROR(SUMPRODUCT((AQ47:AQ56<>"")*(AN47:AN56=TRUE))/SUMPRODUCT((AQ47:AQ56<>"")*1),0) | AO6: =IF(AN6="","",REPT("█",ROUND(AN6*14,0))&REPT("░",14-ROUND(AN6*14,0))) | AT6: =IFERROR(SUMPRODUCT((AW47:AW56<>"")*(AT47:AT56=TRUE))/SUMPRODUCT((AW47:AW56<>"")*1),0) | AU6: =IF(AT6="","",REPT("█",ROUND(AT6*14,0))&REPT("░",14-ROUND(AT6*14,0))) | BA6: =IF(Settings!$B$37="","",Settings!$B$37) | BB6: FALSE | BC6: FALSE | BD6: FALSE | BE6: FALSE | BF6: FALSE | BG6: FALSE | BH6: FALSE | BI6: =IF($BA6="","",COUNTIF(BB6:BH6,TRUE)/7) | BJ6: =IF(BI6="","",REPT("█",ROUND(BI6*10,0))&REPT("░",10-ROUND(BI6*10,0)))
B7: =Calc!D4 | C7: =Calc!E4 | D7: =Calc!F4 | E7: =Calc!G4 | F7: =Calc!H4 | G7: =Calc!I4 | H7: =Calc!J4 | BA7: =IF(Settings!$B$38="","",Settings!$B$38) | BB7: FALSE | BC7: FALSE | BD7: FALSE | BE7: FALSE | BF7: FALSE | BG7: FALSE | BH7: FALSE | BI7: =IF($BA7="","",COUNTIF(BB7:BH7,TRUE)/7) | BJ7: =IF(BI7="","",REPT("█",ROUND(BI7*10,0))&REPT("░",10-ROUND(BI7*10,0)))
B8: =Calc!D5 | C8: =Calc!E5 | D8: =Calc!F5 | E8: =Calc!G5 | F8: =Calc!H5 | G8: =Calc!I5 | H8: =Calc!J5 | J8: =IF(Settings!$C$98="",Settings!$B$98,Settings!$C$98) | P8: =IF(Settings!$C$98="",Settings!$B$98,Settings!$C$98) | V8: =IF(Settings!$C$98="",Settings!$B$98,Settings!$C$98) | AB8: =IF(Settings!$C$98="",Settings!$B$98,Settings!$C$98) | AH8: =IF(Settings!$C$98="",Settings!$B$98,Settings!$C$98) | AN8: =IF(Settings!$C$98="",Settings!$B$98,Settings!$C$98) | AT8: =IF(Settings!$C$98="",Settings!$B$98,Settings!$C$98) | BA8: =IF(Settings!$B$39="","",Settings!$B$39) | BB8: FALSE | BC8: FALSE | BD8: FALSE | BE8: FALSE | BF8: FALSE | BG8: FALSE | BH8: FALSE | BI8: =IF($BA8="","",COUNTIF(BB8:BH8,TRUE)/7) | BJ8: =IF(BI8="","",REPT("█",ROUND(BI8*10,0))&REPT("░",10-ROUND(BI8*10,0)))
B9: =Calc!D6 | C9: =Calc!E6 | D9: =Calc!F6 | E9: =Calc!G6 | F9: =Calc!H6 | G9: =Calc!I6 | H9: =Calc!J6 | J9: =IF(0*Settings!$C$7>=1440,"",MOD(ROUND((Settings!$C$6+0*Settings!$C$7/1440)*1440,0),1440)/1440) | P9: =IF(0*Settings!$C$7>=1440,"",MOD(ROUND((Settings!$C$6+0*Settings!$C$7/1440)*1440,0),1440)/1440) | V9: =IF(0*Settings!$C$7>=1440,"",MOD(ROUND((Settings!$C$6+0*Settings!$C$7/1440)*1440,0),1440)/1440) | AB9: =IF(0*Settings!$C$7>=1440,"",MOD(ROUND((Settings!$C$6+0*Settings!$C$7/1440)*1440,0),1440)/1440) | AH9: =IF(0*Settings!$C$7>=1440,"",MOD(ROUND((Settings!$C$6+0*Settings!$C$7/1440)*1440,0),1440)/1440) | AN9: =IF(0*Settings!$C$7>=1440,"",MOD(ROUND((Settings!$C$6+0*Settings!$C$7/1440)*1440,0),1440)/1440) | AT9: =IF(0*Settings!$C$7>=1440,"",MOD(ROUND((Settings!$C$6+0*Settings!$C$7/1440)*1440,0),1440)/1440) | BA9: =IF(Settings!$B$40="","",Settings!$B$40) | BB9: FALSE | BC9: FALSE | BD9: FALSE | BE9: FALSE | BF9: FALSE | BG9: FALSE | BH9: FALSE | BI9: =IF($BA9="","",COUNTIF(BB9:BH9,TRUE)/7) | BJ9: =IF(BI9="","",REPT("█",ROUND(BI9*10,0))&REPT("░",10-ROUND(BI9*10,0)))
B10: =Calc!D7 | C10: =Calc!E7 | D10: =Calc!F7 | E10: =Calc!G7 | F10: =Calc!H7 | G10: =Calc!I7 | H10: =Calc!J7 | J10: =IF(1*Settings!$C$7>=1440,"",MOD(ROUND((Settings!$C$6+1*Settings!$C$7/1440)*1440,0),1440)/1440) | P10: =IF(1*Settings!$C$7>=1440,"",MOD(ROUND((Settings!$C$6+1*Settings!$C$7/1440)*1440,0),1440)/1440) | V10: =IF(1*Settings!$C$7>=1440,"",MOD(ROUND((Settings!$C$6+1*Settings!$C$7/1440)*1440,0),1440)/1440) | AB10: =IF(1*Settings!$C$7>=1440,"",MOD(ROUND((Settings!$C$6+1*Settings!$C$7/1440)*1440,0),1440)/1440) | AH10: =IF(1*Settings!$C$7>=1440,"",MOD(ROUND((Settings!$C$6+1*Settings!$C$7/1440)*1440,0),1440)/1440) | AN10: =IF(1*Settings!$C$7>=1440,"",MOD(ROUND((Settings!$C$6+1*Settings!$C$7/1440)*1440,0),1440)/1440) | AT10: =IF(1*Settings!$C$7>=1440,"",MOD(ROUND((Settings!$C$6+1*Settings!$C$7/1440)*1440,0),1440)/1440) | BA10: =IF(Settings!$B$41="","",Settings!$B$41) | BB10: FALSE | BC10: FALSE | BD10: FALSE | BE10: FALSE | BF10: FALSE | BG10: FALSE | BH10: FALSE | BI10: =IF($BA10="","",COUNTIF(BB10:BH10,TRUE)/7) | BJ10: =IF(BI10="","",REPT("█",ROUND(BI10*10,0))&REPT("░",10-ROUND(BI10*10,0)))
B11: =Calc!D8 | C11: =Calc!E8 | D11: =Calc!F8 | E11: =Calc!G8 | F11: =Calc!H8 | G11: =Calc!I8 | H11: =Calc!J8 | J11: =IF(2*Settings!$C$7>=1440,"",MOD(ROUND((Settings!$C$6+2*Settings!$C$7/1440)*1440,0),1440)/1440) | P11: =IF(2*Settings!$C$7>=1440,"",MOD(ROUND((Settings!$C$6+2*Settings!$C$7/1440)*1440,0),1440)/1440) | V11: =IF(2*Settings!$C$7>=1440,"",MOD(ROUND((Settings!$C$6+2*Settings!$C$7/1440)*1440,0),1440)/1440) | AB11: =IF(2*Settings!$C$7>=1440,"",MOD(ROUND((Settings!$C$6+2*Settings!$C$7/1440)*1440,0),1440)/1440) | AH11: =IF(2*Settings!$C$7>=1440,"",MOD(ROUND((Settings!$C$6+2*Settings!$C$7/1440)*1440,0),1440)/1440) | AN11: =IF(2*Settings!$C$7>=1440,"",MOD(ROUND((Settings!$C$6+2*Settings!$C$7/1440)*1440,0),1440)/1440) | AT11: =IF(2*Settings!$C$7>=1440,"",MOD(ROUND((Settings!$C$6+2*Settings!$C$7/1440)*1440,0),1440)/1440) | BA11: =IF(Settings!$B$42="","",Settings!$B$42) | BB11: FALSE | BC11: FALSE | BD11: FALSE | BE11: FALSE | BF11: FALSE | BG11: FALSE | BH11: FALSE | BI11: =IF($BA11="","",COUNTIF(BB11:BH11,TRUE)/7) | BJ11: =IF(BI11="","",REPT("█",ROUND(BI11*10,0))&REPT("░",10-ROUND(BI11*10,0)))
J12: =IF(3*Settings!$C$7>=1440,"",MOD(ROUND((Settings!$C$6+3*Settings!$C$7/1440)*1440,0),1440)/1440) | P12: =IF(3*Settings!$C$7>=1440,"",MOD(ROUND((Settings!$C$6+3*Settings!$C$7/1440)*1440,0),1440)/1440) | V12: =IF(3*Settings!$C$7>=1440,"",MOD(ROUND((Settings!$C$6+3*Settings!$C$7/1440)*1440,0),1440)/1440) | AB12: =IF(3*Settings!$C$7>=1440,"",MOD(ROUND((Settings!$C$6+3*Settings!$C$7/1440)*1440,0),1440)/1440) | AH12: =IF(3*Settings!$C$7>=1440,"",MOD(ROUND((Settings!$C$6+3*Settings!$C$7/1440)*1440,0),1440)/1440) | AN12: =IF(3*Settings!$C$7>=1440,"",MOD(ROUND((Settings!$C$6+3*Settings!$C$7/1440)*1440,0),1440)/1440) | AT12: =IF(3*Settings!$C$7>=1440,"",MOD(ROUND((Settings!$C$6+3*Settings!$C$7/1440)*1440,0),1440)/1440) | BA12: =IF(Settings!$B$43="","",Settings!$B$43) | BB12: FALSE | BC12: FALSE | BD12: FALSE | BE12: FALSE | BF12: FALSE | BG12: FALSE | BH12: FALSE | BI12: =IF($BA12="","",COUNTIF(BB12:BH12,TRUE)/7) | BJ12: =IF(BI12="","",REPT("█",ROUND(BI12*10,0))&REPT("░",10-ROUND(BI12*10,0)))
J13: =IF(4*Settings!$C$7>=1440,"",MOD(ROUND((Settings!$C$6+4*Settings!$C$7/1440)*1440,0),1440)/1440) | P13: =IF(4*Settings!$C$7>=1440,"",MOD(ROUND((Settings!$C$6+4*Settings!$C$7/1440)*1440,0),1440)/1440) | V13: =IF(4*Settings!$C$7>=1440,"",MOD(ROUND((Settings!$C$6+4*Settings!$C$7/1440)*1440,0),1440)/1440) | AB13: =IF(4*Settings!$C$7>=1440,"",MOD(ROUND((Settings!$C$6+4*Settings!$C$7/1440)*1440,0),1440)/1440) | AH13: =IF(4*Settings!$C$7>=1440,"",MOD(ROUND((Settings!$C$6+4*Settings!$C$7/1440)*1440,0),1440)/1440) | AN13: =IF(4*Settings!$C$7>=1440,"",MOD(ROUND((Settings!$C$6+4*Settings!$C$7/1440)*1440,0),1440)/1440) | AT13: =IF(4*Settings!$C$7>=1440,"",MOD(ROUND((Settings!$C$6+4*Settings!$C$7/1440)*1440,0),1440)/1440) | BA13: =IF(Settings!$B$44="","",Settings!$B$44) | BB13: FALSE | BC13: FALSE | BD13: FALSE | BE13: FALSE | BF13: FALSE | BG13: FALSE | BH13: FALSE | BI13: =IF($BA13="","",COUNTIF(BB13:BH13,TRUE)/7) | BJ13: =IF(BI13="","",REPT("█",ROUND(BI13*10,0))&REPT("░",10-ROUND(BI13*10,0)))
B14: =IF(Settings!$C$102="",Settings!$B$102,Settings!$C$102) | H14: =IFERROR(SUMPRODUCT((C15:C19<>"")*(B15:B19=TRUE))/SUMPRODUCT((C15:C19<>"")*1),0) | J14: =IF(5*Settings!$C$7>=1440,"",MOD(ROUND((Settings!$C$6+5*Settings!$C$7/1440)*1440,0),1440)/1440) | P14: =IF(5*Settings!$C$7>=1440,"",MOD(ROUND((Settings!$C$6+5*Settings!$C$7/1440)*1440,0),1440)/1440) | V14: =IF(5*Settings!$C$7>=1440,"",MOD(ROUND((Settings!$C$6+5*Settings!$C$7/1440)*1440,0),1440)/1440) | AB14: =IF(5*Settings!$C$7>=1440,"",MOD(ROUND((Settings!$C$6+5*Settings!$C$7/1440)*1440,0),1440)/1440) | AH14: =IF(5*Settings!$C$7>=1440,"",MOD(ROUND((Settings!$C$6+5*Settings!$C$7/1440)*1440,0),1440)/1440) | AN14: =IF(5*Settings!$C$7>=1440,"",MOD(ROUND((Settings!$C$6+5*Settings!$C$7/1440)*1440,0),1440)/1440) | AT14: =IF(5*Settings!$C$7>=1440,"",MOD(ROUND((Settings!$C$6+5*Settings!$C$7/1440)*1440,0),1440)/1440) | BA14: =IF(Settings!$B$45="","",Settings!$B$45) | BB14: FALSE | BC14: FALSE | BD14: FALSE | BE14: FALSE | BF14: FALSE | BG14: FALSE | BH14: FALSE | BI14: =IF($BA14="","",COUNTIF(BB14:BH14,TRUE)/7) | BJ14: =IF(BI14="","",REPT("█",ROUND(BI14*10,0))&REPT("░",10-ROUND(BI14*10,0)))
B15: FALSE | J15: =IF(6*Settings!$C$7>=1440,"",MOD(ROUND((Settings!$C$6+6*Settings!$C$7/1440)*1440,0),1440)/1440) | P15: =IF(6*Settings!$C$7>=1440,"",MOD(ROUND((Settings!$C$6+6*Settings!$C$7/1440)*1440,0),1440)/1440) | V15: =IF(6*Settings!$C$7>=1440,"",MOD(ROUND((Settings!$C$6+6*Settings!$C$7/1440)*1440,0),1440)/1440) | AB15: =IF(6*Settings!$C$7>=1440,"",MOD(ROUND((Settings!$C$6+6*Settings!$C$7/1440)*1440,0),1440)/1440) | AH15: =IF(6*Settings!$C$7>=1440,"",MOD(ROUND((Settings!$C$6+6*Settings!$C$7/1440)*1440,0),1440)/1440) | AN15: =IF(6*Settings!$C$7>=1440,"",MOD(ROUND((Settings!$C$6+6*Settings!$C$7/1440)*1440,0),1440)/1440) | AT15: =IF(6*Settings!$C$7>=1440,"",MOD(ROUND((Settings!$C$6+6*Settings!$C$7/1440)*1440,0),1440)/1440) | BA15: =IF(Settings!$B$46="","",Settings!$B$46) | BB15: FALSE | BC15: FALSE | BD15: FALSE | BE15: FALSE | BF15: FALSE | BG15: FALSE | BH15: FALSE | BI15: =IF($BA15="","",COUNTIF(BB15:BH15,TRUE)/7) | BJ15: =IF(BI15="","",REPT("█",ROUND(BI15*10,0))&REPT("░",10-ROUND(BI15*10,0)))
B16: FALSE | J16: =IF(7*Settings!$C$7>=1440,"",MOD(ROUND((Settings!$C$6+7*Settings!$C$7/1440)*1440,0),1440)/1440) | P16: =IF(7*Settings!$C$7>=1440,"",MOD(ROUND((Settings!$C$6+7*Settings!$C$7/1440)*1440,0),1440)/1440) | V16: =IF(7*Settings!$C$7>=1440,"",MOD(ROUND((Settings!$C$6+7*Settings!$C$7/1440)*1440,0),1440)/1440) | AB16: =IF(7*Settings!$C$7>=1440,"",MOD(ROUND((Settings!$C$6+7*Settings!$C$7/1440)*1440,0),1440)/1440) | AH16: =IF(7*Settings!$C$7>=1440,"",MOD(ROUND((Settings!$C$6+7*Settings!$C$7/1440)*1440,0),1440)/1440) | AN16: =IF(7*Settings!$C$7>=1440,"",MOD(ROUND((Settings!$C$6+7*Settings!$C$7/1440)*1440,0),1440)/1440) | AT16: =IF(7*Settings!$C$7>=1440,"",MOD(ROUND((Settings!$C$6+7*Settings!$C$7/1440)*1440,0),1440)/1440) | BA16: =IF(Settings!$B$47="","",Settings!$B$47) | BB16: FALSE | BC16: FALSE | BD16: FALSE | BE16: FALSE | BF16: FALSE | BG16: FALSE | BH16: FALSE | BI16: =IF($BA16="","",COUNTIF(BB16:BH16,TRUE)/7) | BJ16: =IF(BI16="","",REPT("█",ROUND(BI16*10,0))&REPT("░",10-ROUND(BI16*10,0)))
B17: FALSE | J17: =IF(8*Settings!$C$7>=1440,"",MOD(ROUND((Settings!$C$6+8*Settings!$C$7/1440)*1440,0),1440)/1440) | P17: =IF(8*Settings!$C$7>=1440,"",MOD(ROUND((Settings!$C$6+8*Settings!$C$7/1440)*1440,0),1440)/1440) | V17: =IF(8*Settings!$C$7>=1440,"",MOD(ROUND((Settings!$C$6+8*Settings!$C$7/1440)*1440,0),1440)/1440) | AB17: =IF(8*Settings!$C$7>=1440,"",MOD(ROUND((Settings!$C$6+8*Settings!$C$7/1440)*1440,0),1440)/1440) | AH17: =IF(8*Settings!$C$7>=1440,"",MOD(ROUND((Settings!$C$6+8*Settings!$C$7/1440)*1440,0),1440)/1440) | AN17: =IF(8*Settings!$C$7>=1440,"",MOD(ROUND((Settings!$C$6+8*Settings!$C$7/1440)*1440,0),1440)/1440) | AT17: =IF(8*Settings!$C$7>=1440,"",MOD(ROUND((Settings!$C$6+8*Settings!$C$7/1440)*1440,0),1440)/1440) | BA17: =IF(Settings!$B$48="","",Settings!$B$48) | BB17: FALSE | BC17: FALSE | BD17: FALSE | BE17: FALSE | BF17: FALSE | BG17: FALSE | BH17: FALSE | BI17: =IF($BA17="","",COUNTIF(BB17:BH17,TRUE)/7) | BJ17: =IF(BI17="","",REPT("█",ROUND(BI17*10,0))&REPT("░",10-ROUND(BI17*10,0)))
B18: FALSE | J18: =IF(9*Settings!$C$7>=1440,"",MOD(ROUND((Settings!$C$6+9*Settings!$C$7/1440)*1440,0),1440)/1440) | P18: =IF(9*Settings!$C$7>=1440,"",MOD(ROUND((Settings!$C$6+9*Settings!$C$7/1440)*1440,0),1440)/1440) | V18: =IF(9*Settings!$C$7>=1440,"",MOD(ROUND((Settings!$C$6+9*Settings!$C$7/1440)*1440,0),1440)/1440) | AB18: =IF(9*Settings!$C$7>=1440,"",MOD(ROUND((Settings!$C$6+9*Settings!$C$7/1440)*1440,0),1440)/1440) | AH18: =IF(9*Settings!$C$7>=1440,"",MOD(ROUND((Settings!$C$6+9*Settings!$C$7/1440)*1440,0),1440)/1440) | AN18: =IF(9*Settings!$C$7>=1440,"",MOD(ROUND((Settings!$C$6+9*Settings!$C$7/1440)*1440,0),1440)/1440) | AT18: =IF(9*Settings!$C$7>=1440,"",MOD(ROUND((Settings!$C$6+9*Settings!$C$7/1440)*1440,0),1440)/1440) | BA18: =IF(Settings!$B$49="","",Settings!$B$49) | BB18: FALSE | BC18: FALSE | BD18: FALSE | BE18: FALSE | BF18: FALSE | BG18: FALSE | BH18: FALSE | BI18: =IF($BA18="","",COUNTIF(BB18:BH18,TRUE)/7) | BJ18: =IF(BI18="","",REPT("█",ROUND(BI18*10,0))&REPT("░",10-ROUND(BI18*10,0)))
B19: FALSE | J19: =IF(10*Settings!$C$7>=1440,"",MOD(ROUND((Settings!$C$6+10*Settings!$C$7/1440)*1440,0),1440)/1440) | P19: =IF(10*Settings!$C$7>=1440,"",MOD(ROUND((Settings!$C$6+10*Settings!$C$7/1440)*1440,0),1440)/1440) | V19: =IF(10*Settings!$C$7>=1440,"",MOD(ROUND((Settings!$C$6+10*Settings!$C$7/1440)*1440,0),1440)/1440) | AB19: =IF(10*Settings!$C$7>=1440,"",MOD(ROUND((Settings!$C$6+10*Settings!$C$7/1440)*1440,0),1440)/1440) | AH19: =IF(10*Settings!$C$7>=1440,"",MOD(ROUND((Settings!$C$6+10*Settings!$C$7/1440)*1440,0),1440)/1440) | AN19: =IF(10*Settings!$C$7>=1440,"",MOD(ROUND((Settings!$C$6+10*Settings!$C$7/1440)*1440,0),1440)/1440) | AT19: =IF(10*Settings!$C$7>=1440,"",MOD(ROUND((Settings!$C$6+10*Settings!$C$7/1440)*1440,0),1440)/1440) | BA19: =IF(Settings!$B$50="","",Settings!$B$50) | BB19: FALSE | BC19: FALSE | BD19: FALSE | BE19: FALSE | BF19: FALSE | BG19: FALSE | BH19: FALSE | BI19: =IF($BA19="","",COUNTIF(BB19:BH19,TRUE)/7) | BJ19: =IF(BI19="","",REPT("█",ROUND(BI19*10,0))&REPT("░",10-ROUND(BI19*10,0)))
J20: =IF(11*Settings!$C$7>=1440,"",MOD(ROUND((Settings!$C$6+11*Settings!$C$7/1440)*1440,0),1440)/1440) | P20: =IF(11*Settings!$C$7>=1440,"",MOD(ROUND((Settings!$C$6+11*Settings!$C$7/1440)*1440,0),1440)/1440) | V20: =IF(11*Settings!$C$7>=1440,"",MOD(ROUND((Settings!$C$6+11*Settings!$C$7/1440)*1440,0),1440)/1440) | AB20: =IF(11*Settings!$C$7>=1440,"",MOD(ROUND((Settings!$C$6+11*Settings!$C$7/1440)*1440,0),1440)/1440) | AH20: =IF(11*Settings!$C$7>=1440,"",MOD(ROUND((Settings!$C$6+11*Settings!$C$7/1440)*1440,0),1440)/1440) | AN20: =IF(11*Settings!$C$7>=1440,"",MOD(ROUND((Settings!$C$6+11*Settings!$C$7/1440)*1440,0),1440)/1440) | AT20: =IF(11*Settings!$C$7>=1440,"",MOD(ROUND((Settings!$C$6+11*Settings!$C$7/1440)*1440,0),1440)/1440) | BA20: =IF(Settings!$B$51="","",Settings!$B$51) | BB20: FALSE | BC20: FALSE | BD20: FALSE | BE20: FALSE | BF20: FALSE | BG20: FALSE | BH20: FALSE | BI20: =IF($BA20="","",COUNTIF(BB20:BH20,TRUE)/7) | BJ20: =IF(BI20="","",REPT("█",ROUND(BI20*10,0))&REPT("░",10-ROUND(BI20*10,0)))
J21: =IF(12*Settings!$C$7>=1440,"",MOD(ROUND((Settings!$C$6+12*Settings!$C$7/1440)*1440,0),1440)/1440) | P21: =IF(12*Settings!$C$7>=1440,"",MOD(ROUND((Settings!$C$6+12*Settings!$C$7/1440)*1440,0),1440)/1440) | V21: =IF(12*Settings!$C$7>=1440,"",MOD(ROUND((Settings!$C$6+12*Settings!$C$7/1440)*1440,0),1440)/1440) | AB21: =IF(12*Settings!$C$7>=1440,"",MOD(ROUND((Settings!$C$6+12*Settings!$C$7/1440)*1440,0),1440)/1440) | AH21: =IF(12*Settings!$C$7>=1440,"",MOD(ROUND((Settings!$C$6+12*Settings!$C$7/1440)*1440,0),1440)/1440) | AN21: =IF(12*Settings!$C$7>=1440,"",MOD(ROUND((Settings!$C$6+12*Settings!$C$7/1440)*1440,0),1440)/1440) | AT21: =IF(12*Settings!$C$7>=1440,"",MOD(ROUND((Settings!$C$6+12*Settings!$C$7/1440)*1440,0),1440)/1440) | BA21: =IF(Settings!$B$52="","",Settings!$B$52) | BB21: FALSE | BC21: FALSE | BD21: FALSE | BE21: FALSE | BF21: FALSE | BG21: FALSE | BH21: FALSE | BI21: =IF($BA21="","",COUNTIF(BB21:BH21,TRUE)/7) | BJ21: =IF(BI21="","",REPT("█",ROUND(BI21*10,0))&REPT("░",10-ROUND(BI21*10,0)))
B22: =IF(Settings!$C$103="",Settings!$B$103,Settings!$C$103) | H22: =IFERROR(SUMPRODUCT((C23:C27<>"")*(B23:B27=TRUE))/SUMPRODUCT((C23:C27<>"")*1),0) | J22: =IF(13*Settings!$C$7>=1440,"",MOD(ROUND((Settings!$C$6+13*Settings!$C$7/1440)*1440,0),1440)/1440) | P22: =IF(13*Settings!$C$7>=1440,"",MOD(ROUND((Settings!$C$6+13*Settings!$C$7/1440)*1440,0),1440)/1440) | V22: =IF(13*Settings!$C$7>=1440,"",MOD(ROUND((Settings!$C$6+13*Settings!$C$7/1440)*1440,0),1440)/1440) | AB22: =IF(13*Settings!$C$7>=1440,"",MOD(ROUND((Settings!$C$6+13*Settings!$C$7/1440)*1440,0),1440)/1440) | AH22: =IF(13*Settings!$C$7>=1440,"",MOD(ROUND((Settings!$C$6+13*Settings!$C$7/1440)*1440,0),1440)/1440) | AN22: =IF(13*Settings!$C$7>=1440,"",MOD(ROUND((Settings!$C$6+13*Settings!$C$7/1440)*1440,0),1440)/1440) | AT22: =IF(13*Settings!$C$7>=1440,"",MOD(ROUND((Settings!$C$6+13*Settings!$C$7/1440)*1440,0),1440)/1440) | BA22: =IF(Settings!$B$53="","",Settings!$B$53) | BB22: FALSE | BC22: FALSE | BD22: FALSE | BE22: FALSE | BF22: FALSE | BG22: FALSE | BH22: FALSE | BI22: =IF($BA22="","",COUNTIF(BB22:BH22,TRUE)/7) | BJ22: =IF(BI22="","",REPT("█",ROUND(BI22*10,0))&REPT("░",10-ROUND(BI22*10,0)))
B23: FALSE | J23: =IF(14*Settings!$C$7>=1440,"",MOD(ROUND((Settings!$C$6+14*Settings!$C$7/1440)*1440,0),1440)/1440) | P23: =IF(14*Settings!$C$7>=1440,"",MOD(ROUND((Settings!$C$6+14*Settings!$C$7/1440)*1440,0),1440)/1440) | V23: =IF(14*Settings!$C$7>=1440,"",MOD(ROUND((Settings!$C$6+14*Settings!$C$7/1440)*1440,0),1440)/1440) | AB23: =IF(14*Settings!$C$7>=1440,"",MOD(ROUND((Settings!$C$6+14*Settings!$C$7/1440)*1440,0),1440)/1440) | AH23: =IF(14*Settings!$C$7>=1440,"",MOD(ROUND((Settings!$C$6+14*Settings!$C$7/1440)*1440,0),1440)/1440) | AN23: =IF(14*Settings!$C$7>=1440,"",MOD(ROUND((Settings!$C$6+14*Settings!$C$7/1440)*1440,0),1440)/1440) | AT23: =IF(14*Settings!$C$7>=1440,"",MOD(ROUND((Settings!$C$6+14*Settings!$C$7/1440)*1440,0),1440)/1440) | BA23: =IF(Settings!$B$54="","",Settings!$B$54) | BB23: FALSE | BC23: FALSE | BD23: FALSE | BE23: FALSE | BF23: FALSE | BG23: FALSE | BH23: FALSE | BI23: =IF($BA23="","",COUNTIF(BB23:BH23,TRUE)/7) | BJ23: =IF(BI23="","",REPT("█",ROUND(BI23*10,0))&REPT("░",10-ROUND(BI23*10,0)))
B24: FALSE | J24: =IF(15*Settings!$C$7>=1440,"",MOD(ROUND((Settings!$C$6+15*Settings!$C$7/1440)*1440,0),1440)/1440) | P24: =IF(15*Settings!$C$7>=1440,"",MOD(ROUND((Settings!$C$6+15*Settings!$C$7/1440)*1440,0),1440)/1440) | V24: =IF(15*Settings!$C$7>=1440,"",MOD(ROUND((Settings!$C$6+15*Settings!$C$7/1440)*1440,0),1440)/1440) | AB24: =IF(15*Settings!$C$7>=1440,"",MOD(ROUND((Settings!$C$6+15*Settings!$C$7/1440)*1440,0),1440)/1440) | AH24: =IF(15*Settings!$C$7>=1440,"",MOD(ROUND((Settings!$C$6+15*Settings!$C$7/1440)*1440,0),1440)/1440) | AN24: =IF(15*Settings!$C$7>=1440,"",MOD(ROUND((Settings!$C$6+15*Settings!$C$7/1440)*1440,0),1440)/1440) | AT24: =IF(15*Settings!$C$7>=1440,"",MOD(ROUND((Settings!$C$6+15*Settings!$C$7/1440)*1440,0),1440)/1440) | BA24: =IF(Settings!$B$55="","",Settings!$B$55) | BB24: FALSE | BC24: FALSE | BD24: FALSE | BE24: FALSE | BF24: FALSE | BG24: FALSE | BH24: FALSE | BI24: =IF($BA24="","",COUNTIF(BB24:BH24,TRUE)/7) | BJ24: =IF(BI24="","",REPT("█",ROUND(BI24*10,0))&REPT("░",10-ROUND(BI24*10,0)))
B25: FALSE | J25: =IF(16*Settings!$C$7>=1440,"",MOD(ROUND((Settings!$C$6+16*Settings!$C$7/1440)*1440,0),1440)/1440) | P25: =IF(16*Settings!$C$7>=1440,"",MOD(ROUND((Settings!$C$6+16*Settings!$C$7/1440)*1440,0),1440)/1440) | V25: =IF(16*Settings!$C$7>=1440,"",MOD(ROUND((Settings!$C$6+16*Settings!$C$7/1440)*1440,0),1440)/1440) | AB25: =IF(16*Settings!$C$7>=1440,"",MOD(ROUND((Settings!$C$6+16*Settings!$C$7/1440)*1440,0),1440)/1440) | AH25: =IF(16*Settings!$C$7>=1440,"",MOD(ROUND((Settings!$C$6+16*Settings!$C$7/1440)*1440,0),1440)/1440) | AN25: =IF(16*Settings!$C$7>=1440,"",MOD(ROUND((Settings!$C$6+16*Settings!$C$7/1440)*1440,0),1440)/1440) | AT25: =IF(16*Settings!$C$7>=1440,"",MOD(ROUND((Settings!$C$6+16*Settings!$C$7/1440)*1440,0),1440)/1440) | BA25: =IF(Settings!$B$56="","",Settings!$B$56) | BB25: FALSE | BC25: FALSE | BD25: FALSE | BE25: FALSE | BF25: FALSE | BG25: FALSE | BH25: FALSE | BI25: =IF($BA25="","",COUNTIF(BB25:BH25,TRUE)/7) | BJ25: =IF(BI25="","",REPT("█",ROUND(BI25*10,0))&REPT("░",10-ROUND(BI25*10,0)))
B26: FALSE | J26: =IF(17*Settings!$C$7>=1440,"",MOD(ROUND((Settings!$C$6+17*Settings!$C$7/1440)*1440,0),1440)/1440) | P26: =IF(17*Settings!$C$7>=1440,"",MOD(ROUND((Settings!$C$6+17*Settings!$C$7/1440)*1440,0),1440)/1440) | V26: =IF(17*Settings!$C$7>=1440,"",MOD(ROUND((Settings!$C$6+17*Settings!$C$7/1440)*1440,0),1440)/1440) | AB26: =IF(17*Settings!$C$7>=1440,"",MOD(ROUND((Settings!$C$6+17*Settings!$C$7/1440)*1440,0),1440)/1440) | AH26: =IF(17*Settings!$C$7>=1440,"",MOD(ROUND((Settings!$C$6+17*Settings!$C$7/1440)*1440,0),1440)/1440) | AN26: =IF(17*Settings!$C$7>=1440,"",MOD(ROUND((Settings!$C$6+17*Settings!$C$7/1440)*1440,0),1440)/1440) | AT26: =IF(17*Settings!$C$7>=1440,"",MOD(ROUND((Settings!$C$6+17*Settings!$C$7/1440)*1440,0),1440)/1440) | BA26: =IF(Settings!$B$57="","",Settings!$B$57) | BB26: FALSE | BC26: FALSE | BD26: FALSE | BE26: FALSE | BF26: FALSE | BG26: FALSE | BH26: FALSE | BI26: =IF($BA26="","",COUNTIF(BB26:BH26,TRUE)/7) | BJ26: =IF(BI26="","",REPT("█",ROUND(BI26*10,0))&REPT("░",10-ROUND(BI26*10,0)))
B27: FALSE | J27: =IF(18*Settings!$C$7>=1440,"",MOD(ROUND((Settings!$C$6+18*Settings!$C$7/1440)*1440,0),1440)/1440) | P27: =IF(18*Settings!$C$7>=1440,"",MOD(ROUND((Settings!$C$6+18*Settings!$C$7/1440)*1440,0),1440)/1440) | V27: =IF(18*Settings!$C$7>=1440,"",MOD(ROUND((Settings!$C$6+18*Settings!$C$7/1440)*1440,0),1440)/1440) | AB27: =IF(18*Settings!$C$7>=1440,"",MOD(ROUND((Settings!$C$6+18*Settings!$C$7/1440)*1440,0),1440)/1440) | AH27: =IF(18*Settings!$C$7>=1440,"",MOD(ROUND((Settings!$C$6+18*Settings!$C$7/1440)*1440,0),1440)/1440) | AN27: =IF(18*Settings!$C$7>=1440,"",MOD(ROUND((Settings!$C$6+18*Settings!$C$7/1440)*1440,0),1440)/1440) | AT27: =IF(18*Settings!$C$7>=1440,"",MOD(ROUND((Settings!$C$6+18*Settings!$C$7/1440)*1440,0),1440)/1440) | BA27: Daily completion | BB27: =IFERROR(SUMPRODUCT(($BA$6:$BA$26<>"")*(BB$6:BB$26=TRUE))/SUMPRODUCT(($BA$6:$BA$26<>"")*1),0) | BC27: =IFERROR(SUMPRODUCT(($BA$6:$BA$26<>"")*(BC$6:BC$26=TRUE))/SUMPRODUCT(($BA$6:$BA$26<>"")*1),0) | BD27: =IFERROR(SUMPRODUCT(($BA$6:$BA$26<>"")*(BD$6:BD$26=TRUE))/SUMPRODUCT(($BA$6:$BA$26<>"")*1),0) | BE27: =IFERROR(SUMPRODUCT(($BA$6:$BA$26<>"")*(BE$6:BE$26=TRUE))/SUMPRODUCT(($BA$6:$BA$26<>"")*1),0) | BF27: =IFERROR(SUMPRODUCT(($BA$6:$BA$26<>"")*(BF$6:BF$26=TRUE))/SUMPRODUCT(($BA$6:$BA$26<>"")*1),0) | BG27: =IFERROR(SUMPRODUCT(($BA$6:$BA$26<>"")*(BG$6:BG$26=TRUE))/SUMPRODUCT(($BA$6:$BA$26<>"")*1),0) | BH27: =IFERROR(SUMPRODUCT(($BA$6:$BA$26<>"")*(BH$6:BH$26=TRUE))/SUMPRODUCT(($BA$6:$BA$26<>"")*1),0) | BI27: =IFERROR(SUMPRODUCT(($BA$6:$BA$26<>"")*($BB$6:$BH$26=TRUE))/(SUMPRODUCT(($BA$6:$BA$26<>"")*1)*7),0) | BJ27: =IF(BI27="","",REPT("█",ROUND(BI27*10,0))&REPT("░",10-ROUND(BI27*10,0)))
J28: =IF(19*Settings!$C$7>=1440,"",MOD(ROUND((Settings!$C$6+19*Settings!$C$7/1440)*1440,0),1440)/1440) | P28: =IF(19*Settings!$C$7>=1440,"",MOD(ROUND((Settings!$C$6+19*Settings!$C$7/1440)*1440,0),1440)/1440) | V28: =IF(19*Settings!$C$7>=1440,"",MOD(ROUND((Settings!$C$6+19*Settings!$C$7/1440)*1440,0),1440)/1440) | AB28: =IF(19*Settings!$C$7>=1440,"",MOD(ROUND((Settings!$C$6+19*Settings!$C$7/1440)*1440,0),1440)/1440) | AH28: =IF(19*Settings!$C$7>=1440,"",MOD(ROUND((Settings!$C$6+19*Settings!$C$7/1440)*1440,0),1440)/1440) | AN28: =IF(19*Settings!$C$7>=1440,"",MOD(ROUND((Settings!$C$6+19*Settings!$C$7/1440)*1440,0),1440)/1440) | AT28: =IF(19*Settings!$C$7>=1440,"",MOD(ROUND((Settings!$C$6+19*Settings!$C$7/1440)*1440,0),1440)/1440)
J29: =IF(20*Settings!$C$7>=1440,"",MOD(ROUND((Settings!$C$6+20*Settings!$C$7/1440)*1440,0),1440)/1440) | P29: =IF(20*Settings!$C$7>=1440,"",MOD(ROUND((Settings!$C$6+20*Settings!$C$7/1440)*1440,0),1440)/1440) | V29: =IF(20*Settings!$C$7>=1440,"",MOD(ROUND((Settings!$C$6+20*Settings!$C$7/1440)*1440,0),1440)/1440) | AB29: =IF(20*Settings!$C$7>=1440,"",MOD(ROUND((Settings!$C$6+20*Settings!$C$7/1440)*1440,0),1440)/1440) | AH29: =IF(20*Settings!$C$7>=1440,"",MOD(ROUND((Settings!$C$6+20*Settings!$C$7/1440)*1440,0),1440)/1440) | AN29: =IF(20*Settings!$C$7>=1440,"",MOD(ROUND((Settings!$C$6+20*Settings!$C$7/1440)*1440,0),1440)/1440) | AT29: =IF(20*Settings!$C$7>=1440,"",MOD(ROUND((Settings!$C$6+20*Settings!$C$7/1440)*1440,0),1440)/1440)
J30: =IF(21*Settings!$C$7>=1440,"",MOD(ROUND((Settings!$C$6+21*Settings!$C$7/1440)*1440,0),1440)/1440) | P30: =IF(21*Settings!$C$7>=1440,"",MOD(ROUND((Settings!$C$6+21*Settings!$C$7/1440)*1440,0),1440)/1440) | V30: =IF(21*Settings!$C$7>=1440,"",MOD(ROUND((Settings!$C$6+21*Settings!$C$7/1440)*1440,0),1440)/1440) | AB30: =IF(21*Settings!$C$7>=1440,"",MOD(ROUND((Settings!$C$6+21*Settings!$C$7/1440)*1440,0),1440)/1440) | AH30: =IF(21*Settings!$C$7>=1440,"",MOD(ROUND((Settings!$C$6+21*Settings!$C$7/1440)*1440,0),1440)/1440) | AN30: =IF(21*Settings!$C$7>=1440,"",MOD(ROUND((Settings!$C$6+21*Settings!$C$7/1440)*1440,0),1440)/1440) | AT30: =IF(21*Settings!$C$7>=1440,"",MOD(ROUND((Settings!$C$6+21*Settings!$C$7/1440)*1440,0),1440)/1440) | BA30: =IF(Settings!$C$101="",Settings!$B$101,Settings!$C$101) | BI30: Avg | BJ30: Total
J31: =IF(22*Settings!$C$7>=1440,"",MOD(ROUND((Settings!$C$6+22*Settings!$C$7/1440)*1440,0),1440)/1440) | P31: =IF(22*Settings!$C$7>=1440,"",MOD(ROUND((Settings!$C$6+22*Settings!$C$7/1440)*1440,0),1440)/1440) | V31: =IF(22*Settings!$C$7>=1440,"",MOD(ROUND((Settings!$C$6+22*Settings!$C$7/1440)*1440,0),1440)/1440) | AB31: =IF(22*Settings!$C$7>=1440,"",MOD(ROUND((Settings!$C$6+22*Settings!$C$7/1440)*1440,0),1440)/1440) | AH31: =IF(22*Settings!$C$7>=1440,"",MOD(ROUND((Settings!$C$6+22*Settings!$C$7/1440)*1440,0),1440)/1440) | AN31: =IF(22*Settings!$C$7>=1440,"",MOD(ROUND((Settings!$C$6+22*Settings!$C$7/1440)*1440,0),1440)/1440) | AT31: =IF(22*Settings!$C$7>=1440,"",MOD(ROUND((Settings!$C$6+22*Settings!$C$7/1440)*1440,0),1440)/1440) | BA31: =Settings!$B$61&IF(Settings!$C$61<>""," ("&Settings!$C$61&")","") | BI31: =IFERROR(AVERAGE(BB31:BH31),0) | BJ31: =SUM(BB31:BH31) | BM31: =IF(BB31="","",IFERROR(MIN(1,MAX(0,(BB31-Settings!$D$61)/(Settings!$E$61-Settings!$D$61))),0)) | BN31: =IF(BC31="","",IFERROR(MIN(1,MAX(0,(BC31-Settings!$D$61)/(Settings!$E$61-Settings!$D$61))),0)) | BO31: =IF(BD31="","",IFERROR(MIN(1,MAX(0,(BD31-Settings!$D$61)/(Settings!$E$61-Settings!$D$61))),0)) | BP31: =IF(BE31="","",IFERROR(MIN(1,MAX(0,(BE31-Settings!$D$61)/(Settings!$E$61-Settings!$D$61))),0)) | BQ31: =IF(BF31="","",IFERROR(MIN(1,MAX(0,(BF31-Settings!$D$61)/(Settings!$E$61-Settings!$D$61))),0)) | BR31: =IF(BG31="","",IFERROR(MIN(1,MAX(0,(BG31-Settings!$D$61)/(Settings!$E$61-Settings!$D$61))),0)) | BS31: =IF(BH31="","",IFERROR(MIN(1,MAX(0,(BH31-Settings!$D$61)/(Settings!$E$61-Settings!$D$61))),0)) | BT31: =IFERROR(MIN(1,MAX(0,(BI31-Settings!$D$61)/(Settings!$E$61-Settings!$D$61))),0)
J32: =IF(23*Settings!$C$7>=1440,"",MOD(ROUND((Settings!$C$6+23*Settings!$C$7/1440)*1440,0),1440)/1440) | P32: =IF(23*Settings!$C$7>=1440,"",MOD(ROUND((Settings!$C$6+23*Settings!$C$7/1440)*1440,0),1440)/1440) | V32: =IF(23*Settings!$C$7>=1440,"",MOD(ROUND((Settings!$C$6+23*Settings!$C$7/1440)*1440,0),1440)/1440) | AB32: =IF(23*Settings!$C$7>=1440,"",MOD(ROUND((Settings!$C$6+23*Settings!$C$7/1440)*1440,0),1440)/1440) | AH32: =IF(23*Settings!$C$7>=1440,"",MOD(ROUND((Settings!$C$6+23*Settings!$C$7/1440)*1440,0),1440)/1440) | AN32: =IF(23*Settings!$C$7>=1440,"",MOD(ROUND((Settings!$C$6+23*Settings!$C$7/1440)*1440,0),1440)/1440) | AT32: =IF(23*Settings!$C$7>=1440,"",MOD(ROUND((Settings!$C$6+23*Settings!$C$7/1440)*1440,0),1440)/1440) | BA32: progress | BB32: =IF(BM31="","",REPT("█",ROUND(BM31*5,0))&REPT("░",5-ROUND(BM31*5,0))) | BC32: =IF(BN31="","",REPT("█",ROUND(BN31*5,0))&REPT("░",5-ROUND(BN31*5,0))) | BD32: =IF(BO31="","",REPT("█",ROUND(BO31*5,0))&REPT("░",5-ROUND(BO31*5,0))) | BE32: =IF(BP31="","",REPT("█",ROUND(BP31*5,0))&REPT("░",5-ROUND(BP31*5,0))) | BF32: =IF(BQ31="","",REPT("█",ROUND(BQ31*5,0))&REPT("░",5-ROUND(BQ31*5,0))) | BG32: =IF(BR31="","",REPT("█",ROUND(BR31*5,0))&REPT("░",5-ROUND(BR31*5,0))) | BH32: =IF(BS31="","",REPT("█",ROUND(BS31*5,0))&REPT("░",5-ROUND(BS31*5,0))) | BI32: =IF(BT31="","",REPT("█",ROUND(BT31*5,0))&REPT("░",5-ROUND(BT31*5,0)))
J33: =IF(24*Settings!$C$7>=1440,"",MOD(ROUND((Settings!$C$6+24*Settings!$C$7/1440)*1440,0),1440)/1440) | P33: =IF(24*Settings!$C$7>=1440,"",MOD(ROUND((Settings!$C$6+24*Settings!$C$7/1440)*1440,0),1440)/1440) | V33: =IF(24*Settings!$C$7>=1440,"",MOD(ROUND((Settings!$C$6+24*Settings!$C$7/1440)*1440,0),1440)/1440) | AB33: =IF(24*Settings!$C$7>=1440,"",MOD(ROUND((Settings!$C$6+24*Settings!$C$7/1440)*1440,0),1440)/1440) | AH33: =IF(24*Settings!$C$7>=1440,"",MOD(ROUND((Settings!$C$6+24*Settings!$C$7/1440)*1440,0),1440)/1440) | AN33: =IF(24*Settings!$C$7>=1440,"",MOD(ROUND((Settings!$C$6+24*Settings!$C$7/1440)*1440,0),1440)/1440) | AT33: =IF(24*Settings!$C$7>=1440,"",MOD(ROUND((Settings!$C$6+24*Settings!$C$7/1440)*1440,0),1440)/1440) | BA33: =Settings!$B$62&IF(Settings!$C$62<>""," ("&Settings!$C$62&")","") | BI33: =IFERROR(AVERAGE(BB33:BH33),0) | BJ33: =SUM(BB33:BH33) | BM33: =IF(BB33="","",IFERROR(MIN(1,MAX(0,(BB33-Settings!$D$62)/(Settings!$E$62-Settings!$D$62))),0)) | BN33: =IF(BC33="","",IFERROR(MIN(1,MAX(0,(BC33-Settings!$D$62)/(Settings!$E$62-Settings!$D$62))),0)) | BO33: =IF(BD33="","",IFERROR(MIN(1,MAX(0,(BD33-Settings!$D$62)/(Settings!$E$62-Settings!$D$62))),0)) | BP33: =IF(BE33="","",IFERROR(MIN(1,MAX(0,(BE33-Settings!$D$62)/(Settings!$E$62-Settings!$D$62))),0)) | BQ33: =IF(BF33="","",IFERROR(MIN(1,MAX(0,(BF33-Settings!$D$62)/(Settings!$E$62-Settings!$D$62))),0)) | BR33: =IF(BG33="","",IFERROR(MIN(1,MAX(0,(BG33-Settings!$D$62)/(Settings!$E$62-Settings!$D$62))),0)) | BS33: =IF(BH33="","",IFERROR(MIN(1,MAX(0,(BH33-Settings!$D$62)/(Settings!$E$62-Settings!$D$62))),0)) | BT33: =IFERROR(MIN(1,MAX(0,(BI33-Settings!$D$62)/(Settings!$E$62-Settings!$D$62))),0)
J34: =IF(25*Settings!$C$7>=1440,"",MOD(ROUND((Settings!$C$6+25*Settings!$C$7/1440)*1440,0),1440)/1440) | P34: =IF(25*Settings!$C$7>=1440,"",MOD(ROUND((Settings!$C$6+25*Settings!$C$7/1440)*1440,0),1440)/1440) | V34: =IF(25*Settings!$C$7>=1440,"",MOD(ROUND((Settings!$C$6+25*Settings!$C$7/1440)*1440,0),1440)/1440) | AB34: =IF(25*Settings!$C$7>=1440,"",MOD(ROUND((Settings!$C$6+25*Settings!$C$7/1440)*1440,0),1440)/1440) | AH34: =IF(25*Settings!$C$7>=1440,"",MOD(ROUND((Settings!$C$6+25*Settings!$C$7/1440)*1440,0),1440)/1440) | AN34: =IF(25*Settings!$C$7>=1440,"",MOD(ROUND((Settings!$C$6+25*Settings!$C$7/1440)*1440,0),1440)/1440) | AT34: =IF(25*Settings!$C$7>=1440,"",MOD(ROUND((Settings!$C$6+25*Settings!$C$7/1440)*1440,0),1440)/1440) | BA34: progress | BB34: =IF(BM33="","",REPT("█",ROUND(BM33*5,0))&REPT("░",5-ROUND(BM33*5,0))) | BC34: =IF(BN33="","",REPT("█",ROUND(BN33*5,0))&REPT("░",5-ROUND(BN33*5,0))) | BD34: =IF(BO33="","",REPT("█",ROUND(BO33*5,0))&REPT("░",5-ROUND(BO33*5,0))) | BE34: =IF(BP33="","",REPT("█",ROUND(BP33*5,0))&REPT("░",5-ROUND(BP33*5,0))) | BF34: =IF(BQ33="","",REPT("█",ROUND(BQ33*5,0))&REPT("░",5-ROUND(BQ33*5,0))) | BG34: =IF(BR33="","",REPT("█",ROUND(BR33*5,0))&REPT("░",5-ROUND(BR33*5,0))) | BH34: =IF(BS33="","",REPT("█",ROUND(BS33*5,0))&REPT("░",5-ROUND(BS33*5,0))) | BI34: =IF(BT33="","",REPT("█",ROUND(BT33*5,0))&REPT("░",5-ROUND(BT33*5,0)))
J35: =IF(26*Settings!$C$7>=1440,"",MOD(ROUND((Settings!$C$6+26*Settings!$C$7/1440)*1440,0),1440)/1440) | P35: =IF(26*Settings!$C$7>=1440,"",MOD(ROUND((Settings!$C$6+26*Settings!$C$7/1440)*1440,0),1440)/1440) | V35: =IF(26*Settings!$C$7>=1440,"",MOD(ROUND((Settings!$C$6+26*Settings!$C$7/1440)*1440,0),1440)/1440) | AB35: =IF(26*Settings!$C$7>=1440,"",MOD(ROUND((Settings!$C$6+26*Settings!$C$7/1440)*1440,0),1440)/1440) | AH35: =IF(26*Settings!$C$7>=1440,"",MOD(ROUND((Settings!$C$6+26*Settings!$C$7/1440)*1440,0),1440)/1440) | AN35: =IF(26*Settings!$C$7>=1440,"",MOD(ROUND((Settings!$C$6+26*Settings!$C$7/1440)*1440,0),1440)/1440) | AT35: =IF(26*Settings!$C$7>=1440,"",MOD(ROUND((Settings!$C$6+26*Settings!$C$7/1440)*1440,0),1440)/1440) | BA35: =Settings!$B$63&IF(Settings!$C$63<>""," ("&Settings!$C$63&")","") | BI35: =IFERROR(AVERAGE(BB35:BH35),0) | BJ35: =SUM(BB35:BH35) | BM35: =IF(BB35="","",IFERROR(MIN(1,MAX(0,(BB35-Settings!$D$63)/(Settings!$E$63-Settings!$D$63))),0)) | BN35: =IF(BC35="","",IFERROR(MIN(1,MAX(0,(BC35-Settings!$D$63)/(Settings!$E$63-Settings!$D$63))),0)) | BO35: =IF(BD35="","",IFERROR(MIN(1,MAX(0,(BD35-Settings!$D$63)/(Settings!$E$63-Settings!$D$63))),0)) | BP35: =IF(BE35="","",IFERROR(MIN(1,MAX(0,(BE35-Settings!$D$63)/(Settings!$E$63-Settings!$D$63))),0)) | BQ35: =IF(BF35="","",IFERROR(MIN(1,MAX(0,(BF35-Settings!$D$63)/(Settings!$E$63-Settings!$D$63))),0)) | BR35: =IF(BG35="","",IFERROR(MIN(1,MAX(0,(BG35-Settings!$D$63)/(Settings!$E$63-Settings!$D$63))),0)) | BS35: =IF(BH35="","",IFERROR(MIN(1,MAX(0,(BH35-Settings!$D$63)/(Settings!$E$63-Settings!$D$63))),0)) | BT35: =IFERROR(MIN(1,MAX(0,(BI35-Settings!$D$63)/(Settings!$E$63-Settings!$D$63))),0)
J36: =IF(27*Settings!$C$7>=1440,"",MOD(ROUND((Settings!$C$6+27*Settings!$C$7/1440)*1440,0),1440)/1440) | P36: =IF(27*Settings!$C$7>=1440,"",MOD(ROUND((Settings!$C$6+27*Settings!$C$7/1440)*1440,0),1440)/1440) | V36: =IF(27*Settings!$C$7>=1440,"",MOD(ROUND((Settings!$C$6+27*Settings!$C$7/1440)*1440,0),1440)/1440) | AB36: =IF(27*Settings!$C$7>=1440,"",MOD(ROUND((Settings!$C$6+27*Settings!$C$7/1440)*1440,0),1440)/1440) | AH36: =IF(27*Settings!$C$7>=1440,"",MOD(ROUND((Settings!$C$6+27*Settings!$C$7/1440)*1440,0),1440)/1440) | AN36: =IF(27*Settings!$C$7>=1440,"",MOD(ROUND((Settings!$C$6+27*Settings!$C$7/1440)*1440,0),1440)/1440) | AT36: =IF(27*Settings!$C$7>=1440,"",MOD(ROUND((Settings!$C$6+27*Settings!$C$7/1440)*1440,0),1440)/1440) | BA36: progress | BB36: =IF(BM35="","",REPT("█",ROUND(BM35*5,0))&REPT("░",5-ROUND(BM35*5,0))) | BC36: =IF(BN35="","",REPT("█",ROUND(BN35*5,0))&REPT("░",5-ROUND(BN35*5,0))) | BD36: =IF(BO35="","",REPT("█",ROUND(BO35*5,0))&REPT("░",5-ROUND(BO35*5,0))) | BE36: =IF(BP35="","",REPT("█",ROUND(BP35*5,0))&REPT("░",5-ROUND(BP35*5,0))) | BF36: =IF(BQ35="","",REPT("█",ROUND(BQ35*5,0))&REPT("░",5-ROUND(BQ35*5,0))) | BG36: =IF(BR35="","",REPT("█",ROUND(BR35*5,0))&REPT("░",5-ROUND(BR35*5,0))) | BH36: =IF(BS35="","",REPT("█",ROUND(BS35*5,0))&REPT("░",5-ROUND(BS35*5,0))) | BI36: =IF(BT35="","",REPT("█",ROUND(BT35*5,0))&REPT("░",5-ROUND(BT35*5,0)))
J37: =IF(28*Settings!$C$7>=1440,"",MOD(ROUND((Settings!$C$6+28*Settings!$C$7/1440)*1440,0),1440)/1440) | P37: =IF(28*Settings!$C$7>=1440,"",MOD(ROUND((Settings!$C$6+28*Settings!$C$7/1440)*1440,0),1440)/1440) | V37: =IF(28*Settings!$C$7>=1440,"",MOD(ROUND((Settings!$C$6+28*Settings!$C$7/1440)*1440,0),1440)/1440) | AB37: =IF(28*Settings!$C$7>=1440,"",MOD(ROUND((Settings!$C$6+28*Settings!$C$7/1440)*1440,0),1440)/1440) | AH37: =IF(28*Settings!$C$7>=1440,"",MOD(ROUND((Settings!$C$6+28*Settings!$C$7/1440)*1440,0),1440)/1440) | AN37: =IF(28*Settings!$C$7>=1440,"",MOD(ROUND((Settings!$C$6+28*Settings!$C$7/1440)*1440,0),1440)/1440) | AT37: =IF(28*Settings!$C$7>=1440,"",MOD(ROUND((Settings!$C$6+28*Settings!$C$7/1440)*1440,0),1440)/1440) | BA37: =Settings!$B$64&IF(Settings!$C$64<>""," ("&Settings!$C$64&")","") | BI37: =IFERROR(AVERAGE(BB37:BH37),0) | BJ37: =SUM(BB37:BH37) | BM37: =IF(BB37="","",IFERROR(MIN(1,MAX(0,(BB37-Settings!$D$64)/(Settings!$E$64-Settings!$D$64))),0)) | BN37: =IF(BC37="","",IFERROR(MIN(1,MAX(0,(BC37-Settings!$D$64)/(Settings!$E$64-Settings!$D$64))),0)) | BO37: =IF(BD37="","",IFERROR(MIN(1,MAX(0,(BD37-Settings!$D$64)/(Settings!$E$64-Settings!$D$64))),0)) | BP37: =IF(BE37="","",IFERROR(MIN(1,MAX(0,(BE37-Settings!$D$64)/(Settings!$E$64-Settings!$D$64))),0)) | BQ37: =IF(BF37="","",IFERROR(MIN(1,MAX(0,(BF37-Settings!$D$64)/(Settings!$E$64-Settings!$D$64))),0)) | BR37: =IF(BG37="","",IFERROR(MIN(1,MAX(0,(BG37-Settings!$D$64)/(Settings!$E$64-Settings!$D$64))),0)) | BS37: =IF(BH37="","",IFERROR(MIN(1,MAX(0,(BH37-Settings!$D$64)/(Settings!$E$64-Settings!$D$64))),0)) | BT37: =IFERROR(MIN(1,MAX(0,(BI37-Settings!$D$64)/(Settings!$E$64-Settings!$D$64))),0)
J38: =IF(29*Settings!$C$7>=1440,"",MOD(ROUND((Settings!$C$6+29*Settings!$C$7/1440)*1440,0),1440)/1440) | P38: =IF(29*Settings!$C$7>=1440,"",MOD(ROUND((Settings!$C$6+29*Settings!$C$7/1440)*1440,0),1440)/1440) | V38: =IF(29*Settings!$C$7>=1440,"",MOD(ROUND((Settings!$C$6+29*Settings!$C$7/1440)*1440,0),1440)/1440) | AB38: =IF(29*Settings!$C$7>=1440,"",MOD(ROUND((Settings!$C$6+29*Settings!$C$7/1440)*1440,0),1440)/1440) | AH38: =IF(29*Settings!$C$7>=1440,"",MOD(ROUND((Settings!$C$6+29*Settings!$C$7/1440)*1440,0),1440)/1440) | AN38: =IF(29*Settings!$C$7>=1440,"",MOD(ROUND((Settings!$C$6+29*Settings!$C$7/1440)*1440,0),1440)/1440) | AT38: =IF(29*Settings!$C$7>=1440,"",MOD(ROUND((Settings!$C$6+29*Settings!$C$7/1440)*1440,0),1440)/1440) | BA38: progress | BB38: =IF(BM37="","",REPT("█",ROUND(BM37*5,0))&REPT("░",5-ROUND(BM37*5,0))) | BC38: =IF(BN37="","",REPT("█",ROUND(BN37*5,0))&REPT("░",5-ROUND(BN37*5,0))) | BD38: =IF(BO37="","",REPT("█",ROUND(BO37*5,0))&REPT("░",5-ROUND(BO37*5,0))) | BE38: =IF(BP37="","",REPT("█",ROUND(BP37*5,0))&REPT("░",5-ROUND(BP37*5,0))) | BF38: =IF(BQ37="","",REPT("█",ROUND(BQ37*5,0))&REPT("░",5-ROUND(BQ37*5,0))) | BG38: =IF(BR37="","",REPT("█",ROUND(BR37*5,0))&REPT("░",5-ROUND(BR37*5,0))) | BH38: =IF(BS37="","",REPT("█",ROUND(BS37*5,0))&REPT("░",5-ROUND(BS37*5,0))) | BI38: =IF(BT37="","",REPT("█",ROUND(BT37*5,0))&REPT("░",5-ROUND(BT37*5,0)))
J39: =IF(30*Settings!$C$7>=1440,"",MOD(ROUND((Settings!$C$6+30*Settings!$C$7/1440)*1440,0),1440)/1440) | P39: =IF(30*Settings!$C$7>=1440,"",MOD(ROUND((Settings!$C$6+30*Settings!$C$7/1440)*1440,0),1440)/1440) | V39: =IF(30*Settings!$C$7>=1440,"",MOD(ROUND((Settings!$C$6+30*Settings!$C$7/1440)*1440,0),1440)/1440) | AB39: =IF(30*Settings!$C$7>=1440,"",MOD(ROUND((Settings!$C$6+30*Settings!$C$7/1440)*1440,0),1440)/1440) | AH39: =IF(30*Settings!$C$7>=1440,"",MOD(ROUND((Settings!$C$6+30*Settings!$C$7/1440)*1440,0),1440)/1440) | AN39: =IF(30*Settings!$C$7>=1440,"",MOD(ROUND((Settings!$C$6+30*Settings!$C$7/1440)*1440,0),1440)/1440) | AT39: =IF(30*Settings!$C$7>=1440,"",MOD(ROUND((Settings!$C$6+30*Settings!$C$7/1440)*1440,0),1440)/1440) | BA39: =Settings!$B$65&IF(Settings!$C$65<>""," ("&Settings!$C$65&")","") | BI39: =IFERROR(AVERAGE(BB39:BH39),0) | BJ39: =SUM(BB39:BH39) | BM39: =IF(BB39="","",IFERROR(MIN(1,MAX(0,(BB39-Settings!$D$65)/(Settings!$E$65-Settings!$D$65))),0)) | BN39: =IF(BC39="","",IFERROR(MIN(1,MAX(0,(BC39-Settings!$D$65)/(Settings!$E$65-Settings!$D$65))),0)) | BO39: =IF(BD39="","",IFERROR(MIN(1,MAX(0,(BD39-Settings!$D$65)/(Settings!$E$65-Settings!$D$65))),0)) | BP39: =IF(BE39="","",IFERROR(MIN(1,MAX(0,(BE39-Settings!$D$65)/(Settings!$E$65-Settings!$D$65))),0)) | BQ39: =IF(BF39="","",IFERROR(MIN(1,MAX(0,(BF39-Settings!$D$65)/(Settings!$E$65-Settings!$D$65))),0)) | BR39: =IF(BG39="","",IFERROR(MIN(1,MAX(0,(BG39-Settings!$D$65)/(Settings!$E$65-Settings!$D$65))),0)) | BS39: =IF(BH39="","",IFERROR(MIN(1,MAX(0,(BH39-Settings!$D$65)/(Settings!$E$65-Settings!$D$65))),0)) | BT39: =IFERROR(MIN(1,MAX(0,(BI39-Settings!$D$65)/(Settings!$E$65-Settings!$D$65))),0)
J40: =IF(31*Settings!$C$7>=1440,"",MOD(ROUND((Settings!$C$6+31*Settings!$C$7/1440)*1440,0),1440)/1440) | P40: =IF(31*Settings!$C$7>=1440,"",MOD(ROUND((Settings!$C$6+31*Settings!$C$7/1440)*1440,0),1440)/1440) | V40: =IF(31*Settings!$C$7>=1440,"",MOD(ROUND((Settings!$C$6+31*Settings!$C$7/1440)*1440,0),1440)/1440) | AB40: =IF(31*Settings!$C$7>=1440,"",MOD(ROUND((Settings!$C$6+31*Settings!$C$7/1440)*1440,0),1440)/1440) | AH40: =IF(31*Settings!$C$7>=1440,"",MOD(ROUND((Settings!$C$6+31*Settings!$C$7/1440)*1440,0),1440)/1440) | AN40: =IF(31*Settings!$C$7>=1440,"",MOD(ROUND((Settings!$C$6+31*Settings!$C$7/1440)*1440,0),1440)/1440) | AT40: =IF(31*Settings!$C$7>=1440,"",MOD(ROUND((Settings!$C$6+31*Settings!$C$7/1440)*1440,0),1440)/1440) | BA40: progress | BB40: =IF(BM39="","",REPT("█",ROUND(BM39*5,0))&REPT("░",5-ROUND(BM39*5,0))) | BC40: =IF(BN39="","",REPT("█",ROUND(BN39*5,0))&REPT("░",5-ROUND(BN39*5,0))) | BD40: =IF(BO39="","",REPT("█",ROUND(BO39*5,0))&REPT("░",5-ROUND(BO39*5,0))) | BE40: =IF(BP39="","",REPT("█",ROUND(BP39*5,0))&REPT("░",5-ROUND(BP39*5,0))) | BF40: =IF(BQ39="","",REPT("█",ROUND(BQ39*5,0))&REPT("░",5-ROUND(BQ39*5,0))) | BG40: =IF(BR39="","",REPT("█",ROUND(BR39*5,0))&REPT("░",5-ROUND(BR39*5,0))) | BH40: =IF(BS39="","",REPT("█",ROUND(BS39*5,0))&REPT("░",5-ROUND(BS39*5,0))) | BI40: =IF(BT39="","",REPT("█",ROUND(BT39*5,0))&REPT("░",5-ROUND(BT39*5,0)))
...

Sheet W2
B1: =Calc!M3&" · "&INDEX(Calc!$F$10:$F$15,$B$2) | H1: =Calc!$B$1
B2: 2 | D2: =HYPERLINK("#'Month'!A1","◀ Month") | F2: =HYPERLINK("#'W1'!A1","‹ Prev") | H2: =HYPERLINK("#'W3'!A1","Next ›")
B3: =IF(INDEX(Calc!$E$10:$E$15,$B$2),"","This week is not used in "&Calc!$M$2&".")
BA4: =IF(Settings!$C$100="",Settings!$B$100,Settings!$C$100)
B5: =LEFT(Calc!D1,2) | C5: =LEFT(Calc!E1,2) | D5: =LEFT(Calc!F1,2) | E5: =LEFT(Calc!G1,2) | F5: =LEFT(Calc!H1,2) | G5: =LEFT(Calc!I1,2) | H5: =LEFT(Calc!J1,2) | J5: =IF(INDEX(Settings!$C$69:$C$75,WEEKDAY($N$5,1))="",INDEX(Settings!$B$69:$B$75,WEEKDAY($N$5,1)),INDEX(Settings!$C$69:$C$75,WEEKDAY($N$5,1))) | N5: =INDEX(Calc!$D$3:$J$8,$B$2,1) | P5: =IF(INDEX(Settings!$C$69:$C$75,WEEKDAY($T$5,1))="",INDEX(Settings!$B$69:$B$75,WEEKDAY($T$5,1)),INDEX(Settings!$C$69:$C$75,WEEKDAY($T$5,1))) | T5: =INDEX(Calc!$D$3:$J$8,$B$2,2) | V5: =IF(INDEX(Settings!$C$69:$C$75,WEEKDAY($Z$5,1))="",INDEX(Settings!$B$69:$B$75,WEEKDAY($Z$5,1)),INDEX(Settings!$C$69:$C$75,WEEKDAY($Z$5,1))) | Z5: =INDEX(Calc!$D$3:$J$8,$B$2,3) | AB5: =IF(INDEX(Settings!$C$69:$C$75,WEEKDAY($AF$5,1))="",INDEX(Settings!$B$69:$B$75,WEEKDAY($AF$5,1)),INDEX(Settings!$C$69:$C$75,WEEKDAY($AF$5,1))) | AF5: =INDEX(Calc!$D$3:$J$8,$B$2,4) | AH5: =IF(INDEX(Settings!$C$69:$C$75,WEEKDAY($AL$5,1))="",INDEX(Settings!$B$69:$B$75,WEEKDAY($AL$5,1)),INDEX(Settings!$C$69:$C$75,WEEKDAY($AL$5,1))) | AL5: =INDEX(Calc!$D$3:$J$8,$B$2,5) | AN5: =IF(INDEX(Settings!$C$69:$C$75,WEEKDAY($AR$5,1))="",INDEX(Settings!$B$69:$B$75,WEEKDAY($AR$5,1)),INDEX(Settings!$C$69:$C$75,WEEKDAY($AR$5,1))) | AR5: =INDEX(Calc!$D$3:$J$8,$B$2,6) | AT5: =IF(INDEX(Settings!$C$69:$C$75,WEEKDAY($AX$5,1))="",INDEX(Settings!$B$69:$B$75,WEEKDAY($AX$5,1)),INDEX(Settings!$C$69:$C$75,WEEKDAY($AX$5,1))) | AX5: =INDEX(Calc!$D$3:$J$8,$B$2,7) | BB5: =LEFT(IF(INDEX(Settings!$C$69:$C$75,WEEKDAY(INDEX(Calc!$D$3:$J$8,$B$2,1),1))="",INDEX(Settings!$B$69:$B$75,WEEKDAY(INDEX(Calc!$D$3:$J$8,$B$2,1),1)),INDEX(Settings!$C$69:$C$75,WEEKDAY(INDEX(Calc!$D$3:$J$8,$B$2,1),1))),3) | BC5: =LEFT(IF(INDEX(Settings!$C$69:$C$75,WEEKDAY(INDEX(Calc!$D$3:$J$8,$B$2,2),1))="",INDEX(Settings!$B$69:$B$75,WEEKDAY(INDEX(Calc!$D$3:$J$8,$B$2,2),1)),INDEX(Settings!$C$69:$C$75,WEEKDAY(INDEX(Calc!$D$3:$J$8,$B$2,2),1))),3) | BD5: =LEFT(IF(INDEX(Settings!$C$69:$C$75,WEEKDAY(INDEX(Calc!$D$3:$J$8,$B$2,3),1))="",INDEX(Settings!$B$69:$B$75,WEEKDAY(INDEX(Calc!$D$3:$J$8,$B$2,3),1)),INDEX(Settings!$C$69:$C$75,WEEKDAY(INDEX(Calc!$D$3:$J$8,$B$2,3),1))),3) | BE5: =LEFT(IF(INDEX(Settings!$C$69:$C$75,WEEKDAY(INDEX(Calc!$D$3:$J$8,$B$2,4),1))="",INDEX(Settings!$B$69:$B$75,WEEKDAY(INDEX(Calc!$D$3:$J$8,$B$2,4),1)),INDEX(Settings!$C$69:$C$75,WEEKDAY(INDEX(Calc!$D$3:$J$8,$B$2,4),1))),3) | BF5: =LEFT(IF(INDEX(Settings!$C$69:$C$75,WEEKDAY(INDEX(Calc!$D$3:$J$8,$B$2,5),1))="",INDEX(Settings!$B$69:$B$75,WEEKDAY(INDEX(Calc!$D$3:$J$8,$B$2,5),1)),INDEX(Settings!$C$69:$C$75,WEEKDAY(INDEX(Calc!$D$3:$J$8,$B$2,5),1))),3) | BG5: =LEFT(IF(INDEX(Settings!$C$69:$C$75,WEEKDAY(INDEX(Calc!$D$3:$J$8,$B$2,6),1))="",INDEX(Settings!$B$69:$B$75,WEEKDAY(INDEX(Calc!$D$3:$J$8,$B$2,6),1)),INDEX(Settings!$C$69:$C$75,WEEKDAY(INDEX(Calc!$D$3:$J$8,$B$2,6),1))),3) | BH5: =LEFT(IF(INDEX(Settings!$C$69:$C$75,WEEKDAY(INDEX(Calc!$D$3:$J$8,$B$2,7),1))="",INDEX(Settings!$B$69:$B$75,WEEKDAY(INDEX(Calc!$D$3:$J$8,$B$2,7),1)),INDEX(Settings!$C$69:$C$75,WEEKDAY(INDEX(Calc!$D$3:$J$8,$B$2,7),1))),3) | BI5: % | BJ5: Progress
B6: =Calc!D3 | C6: =Calc!E3 | D6: =Calc!F3 | E6: =Calc!G3 | F6: =Calc!H3 | G6: =Calc!I3 | H6: =Calc!J3 | J6: =IFERROR(SUMPRODUCT((M47:M56<>"")*(J47:J56=TRUE))/SUMPRODUCT((M47:M56<>"")*1),0) | K6: =IF(J6="","",REPT("█",ROUND(J6*14,0))&REPT("░",14-ROUND(J6*14,0))) | P6: =IFERROR(SUMPRODUCT((S47:S56<>"")*(P47:P56=TRUE))/SUMPRODUCT((S47:S56<>"")*1),0) | Q6: =IF(P6="","",REPT("█",ROUND(P6*14,0))&REPT("░",14-ROUND(P6*14,0))) | V6: =IFERROR(SUMPRODUCT((Y47:Y56<>"")*(V47:V56=TRUE))/SUMPRODUCT((Y47:Y56<>"")*1),0) | W6: =IF(V6="","",REPT("█",ROUND(V6*14,0))&REPT("░",14-ROUND(V6*14,0))) | AB6: =IFERROR(SUMPRODUCT((AE47:AE56<>"")*(AB47:AB56=TRUE))/SUMPRODUCT((AE47:AE56<>"")*1),0) | AC6: =IF(AB6="","",REPT("█",ROUND(AB6*14,0))&REPT("░",14-ROUND(AB6*14,0))) | AH6: =IFERROR(SUMPRODUCT((AK47:AK56<>"")*(AH47:AH56=TRUE))/SUMPRODUCT((AK47:AK56<>"")*1),0) | AI6: =IF(AH6="","",REPT("█",ROUND(AH6*14,0))&REPT("░",14-ROUND(AH6*14,0))) | AN6: =IFERROR(SUMPRODUCT((AQ47:AQ56<>"")*(AN47:AN56=TRUE))/SUMPRODUCT((AQ47:AQ56<>"")*1),0) | AO6: =IF(AN6="","",REPT("█",ROUND(AN6*14,0))&REPT("░",14-ROUND(AN6*14,0))) | AT6: =IFERROR(SUMPRODUCT((AW47:AW56<>"")*(AT47:AT56=TRUE))/SUMPRODUCT((AW47:AW56<>"")*1),0) | AU6: =IF(AT6="","",REPT("█",ROUND(AT6*14,0))&REPT("░",14-ROUND(AT6*14,0))) | BA6: =IF(Settings!$B$37="","",Settings!$B$37) | BB6: FALSE | BC6: FALSE | BD6: FALSE | BE6: FALSE | BF6: FALSE | BG6: FALSE | BH6: FALSE | BI6: =IF($BA6="","",COUNTIF(BB6:BH6,TRUE)/7) | BJ6: =IF(BI6="","",REPT("█",ROUND(BI6*10,0))&REPT("░",10-ROUND(BI6*10,0)))
B7: =Calc!D4 | C7: =Calc!E4 | D7: =Calc!F4 | E7: =Calc!G4 | F7: =Calc!H4 | G7: =Calc!I4 | H7: =Calc!J4 | BA7: =IF(Settings!$B$38="","",Settings!$B$38) | BB7: FALSE | BC7: FALSE | BD7: FALSE | BE7: FALSE | BF7: FALSE | BG7: FALSE | BH7: FALSE | BI7: =IF($BA7="","",COUNTIF(BB7:BH7,TRUE)/7) | BJ7: =IF(BI7="","",REPT("█",ROUND(BI7*10,0))&REPT("░",10-ROUND(BI7*10,0)))
B8: =Calc!D5 | C8: =Calc!E5 | D8: =Calc!F5 | E8: =Calc!G5 | F8: =Calc!H5 | G8: =Calc!I5 | H8: =Calc!J5 | J8: =IF(Settings!$C$98="",Settings!$B$98,Settings!$C$98) | P8: =IF(Settings!$C$98="",Settings!$B$98,Settings!$C$98) | V8: =IF(Settings!$C$98="",Settings!$B$98,Settings!$C$98) | AB8: =IF(Settings!$C$98="",Settings!$B$98,Settings!$C$98) | AH8: =IF(Settings!$C$98="",Settings!$B$98,Settings!$C$98) | AN8: =IF(Settings!$C$98="",Settings!$B$98,Settings!$C$98) | AT8: =IF(Settings!$C$98="",Settings!$B$98,Settings!$C$98) | BA8: =IF(Settings!$B$39="","",Settings!$B$39) | BB8: FALSE | BC8: FALSE | BD8: FALSE | BE8: FALSE | BF8: FALSE | BG8: FALSE | BH8: FALSE | BI8: =IF($BA8="","",COUNTIF(BB8:BH8,TRUE)/7) | BJ8: =IF(BI8="","",REPT("█",ROUND(BI8*10,0))&REPT("░",10-ROUND(BI8*10,0)))
B9: =Calc!D6 | C9: =Calc!E6 | D9: =Calc!F6 | E9: =Calc!G6 | F9: =Calc!H6 | G9: =Calc!I6 | H9: =Calc!J6 | J9: =IF(0*Settings!$C$7>=1440,"",MOD(ROUND((Settings!$C$6+0*Settings!$C$7/1440)*1440,0),1440)/1440) | P9: =IF(0*Settings!$C$7>=1440,"",MOD(ROUND((Settings!$C$6+0*Settings!$C$7/1440)*1440,0),1440)/1440) | V9: =IF(0*Settings!$C$7>=1440,"",MOD(ROUND((Settings!$C$6+0*Settings!$C$7/1440)*1440,0),1440)/1440) | AB9: =IF(0*Settings!$C$7>=1440,"",MOD(ROUND((Settings!$C$6+0*Settings!$C$7/1440)*1440,0),1440)/1440) | AH9: =IF(0*Settings!$C$7>=1440,"",MOD(ROUND((Settings!$C$6+0*Settings!$C$7/1440)*1440,0),1440)/1440) | AN9: =IF(0*Settings!$C$7>=1440,"",MOD(ROUND((Settings!$C$6+0*Settings!$C$7/1440)*1440,0),1440)/1440) | AT9: =IF(0*Settings!$C$7>=1440,"",MOD(ROUND((Settings!$C$6+0*Settings!$C$7/1440)*1440,0),1440)/1440) | BA9: =IF(Settings!$B$40="","",Settings!$B$40) | BB9: FALSE | BC9: FALSE | BD9: FALSE | BE9: FALSE | BF9: FALSE | BG9: FALSE | BH9: FALSE | BI9: =IF($BA9="","",COUNTIF(BB9:BH9,TRUE)/7) | BJ9: =IF(BI9="","",REPT("█",ROUND(BI9*10,0))&REPT("░",10-ROUND(BI9*10,0)))
B10: =Calc!D7 | C10: =Calc!E7 | D10: =Calc!F7 | E10: =Calc!G7 | F10: =Calc!H7 | G10: =Calc!I7 | H10: =Calc!J7 | J10: =IF(1*Settings!$C$7>=1440,"",MOD(ROUND((Settings!$C$6+1*Settings!$C$7/1440)*1440,0),1440)/1440) | P10: =IF(1*Settings!$C$7>=1440,"",MOD(ROUND((Settings!$C$6+1*Settings!$C$7/1440)*1440,0),1440)/1440) | V10: =IF(1*Settings!$C$7>=1440,"",MOD(ROUND((Settings!$C$6+1*Settings!$C$7/1440)*1440,0),1440)/1440) | AB10: =IF(1*Settings!$C$7>=1440,"",MOD(ROUND((Settings!$C$6+1*Settings!$C$7/1440)*1440,0),1440)/1440) | AH10: =IF(1*Settings!$C$7>=1440,"",MOD(ROUND((Settings!$C$6+1*Settings!$C$7/1440)*1440,0),1440)/1440) | AN10: =IF(1*Settings!$C$7>=1440,"",MOD(ROUND((Settings!$C$6+1*Settings!$C$7/1440)*1440,0),1440)/1440) | AT10: =IF(1*Settings!$C$7>=1440,"",MOD(ROUND((Settings!$C$6+1*Settings!$C$7/1440)*1440,0),1440)/1440) | BA10: =IF(Settings!$B$41="","",Settings!$B$41) | BB10: FALSE | BC10: FALSE | BD10: FALSE | BE10: FALSE | BF10: FALSE | BG10: FALSE | BH10: FALSE | BI10: =IF($BA10="","",COUNTIF(BB10:BH10,TRUE)/7) | BJ10: =IF(BI10="","",REPT("█",ROUND(BI10*10,0))&REPT("░",10-ROUND(BI10*10,0)))
B11: =Calc!D8 | C11: =Calc!E8 | D11: =Calc!F8 | E11: =Calc!G8 | F11: =Calc!H8 | G11: =Calc!I8 | H11: =Calc!J8 | J11: =IF(2*Settings!$C$7>=1440,"",MOD(ROUND((Settings!$C$6+2*Settings!$C$7/1440)*1440,0),1440)/1440) | P11: =IF(2*Settings!$C$7>=1440,"",MOD(ROUND((Settings!$C$6+2*Settings!$C$7/1440)*1440,0),1440)/1440) | V11: =IF(2*Settings!$C$7>=1440,"",MOD(ROUND((Settings!$C$6+2*Settings!$C$7/1440)*1440,0),1440)/1440) | AB11: =IF(2*Settings!$C$7>=1440,"",MOD(ROUND((Settings!$C$6+2*Settings!$C$7/1440)*1440,0),1440)/1440) | AH11: =IF(2*Settings!$C$7>=1440,"",MOD(ROUND((Settings!$C$6+2*Settings!$C$7/1440)*1440,0),1440)/1440) | AN11: =IF(2*Settings!$C$7>=1440,"",MOD(ROUND((Settings!$C$6+2*Settings!$C$7/1440)*1440,0),1440)/1440) | AT11: =IF(2*Settings!$C$7>=1440,"",MOD(ROUND((Settings!$C$6+2*Settings!$C$7/1440)*1440,0),1440)/1440) | BA11: =IF(Settings!$B$42="","",Settings!$B$42) | BB11: FALSE | BC11: FALSE | BD11: FALSE | BE11: FALSE | BF11: FALSE | BG11: FALSE | BH11: FALSE | BI11: =IF($BA11="","",COUNTIF(BB11:BH11,TRUE)/7) | BJ11: =IF(BI11="","",REPT("█",ROUND(BI11*10,0))&REPT("░",10-ROUND(BI11*10,0)))
